{
    "type": "bundle",
    "id": "bundle--4b709105-98af-40af-9a7f-4939c075e12d",
    "objects": [
        {
            "type": "vulnerability",
            "spec_version": "2.1",
            "id": "vulnerability--c670abe3-9a3e-4834-881b-b8ffeff3fdca",
            "created_by_ref": "identity--8ce3f695-d5a4-4dc8-9e93-a65af453a31a",
            "created": "2025-05-16T02:01:19.739739Z",
            "modified": "2025-05-16T02:01:19.739739Z",
            "name": "CVE-2025-4516",
            "description": "There is an issue in CPython when using `bytes.decode(\"unicode_escape\", error=\"ignore|replace\")`. If you are not using the \"unicode_escape\" encoding or an error handler your usage is not affected. To work-around this issue you may stop using the error= handler and instead wrap the bytes.decode() call in a try-except catching the DecodeError.",
            "external_references": [
                {
                    "source_name": "cve",
                    "external_id": "CVE-2025-4516"
                }
            ]
        }
    ]
}