{
    "type": "bundle",
    "id": "bundle--d50c83c5-eb01-401f-b4c0-661c6d38519a",
    "objects": [
        {
            "type": "vulnerability",
            "spec_version": "2.1",
            "id": "vulnerability--4f57791e-1448-4283-8780-f403dbf2403e",
            "created_by_ref": "identity--8ce3f695-d5a4-4dc8-9e93-a65af453a31a",
            "created": "2024-10-16T01:45:28.047598Z",
            "modified": "2024-10-16T01:45:28.047598Z",
            "name": "CVE-2024-9979",
            "description": "A flaw was found in PyO3. This vulnerability causes a use-after-free issue, potentially leading to memory corruption or crashes via unsound borrowing from weak Python references.",
            "external_references": [
                {
                    "source_name": "cve",
                    "external_id": "CVE-2024-9979"
                }
            ]
        }
    ]
}